# catch II

'catch' tambiÃ©n capturarÃ¡ un error emitido desde una promesa resuelta:

<code><pre>
let promise = new Promise((resolve, reject) => {
  resolve('success');
});
promise.then(response => {
  throw new Error('nunca jamÃ¡s!')
}).catch(error => {
  console.log("Promesa rechazada ğŸ˜¢ ", error); // nunca jamÃ¡s!
});
</pre></code>
